analysis/replay/replay_0922.json
{
  "strike_min": 5438.5,
  "strike_max": 5540.0,
  "num_lanes": 24,
  "frames": [
    {
      "frame_index": 0,
      "timestamp": "2025-04-14T09:22:00.316756-04:00",
      "life_progress": 0.0,
      "liquidity_density_factor": 0.625,
      "gamma_metabolism_factor": 0.450667,
      "manipulation_factor": 0.0,
      "price_kinetic_factor": 0.0,
      "health_score": 0.80855,
      "health_state": "stable",
      "ask_flow": [
        0.0,
        0.0,
        0.0,
        0.0,
        0.0,
        0.0,
        0.0,
        0.0,
        0.0,
        0.0,
        0.0,
        0.0,
        0.155311,
        0.257875,
        0.704762,
        0.355311,
        0.16337,
        0.151648,
        0.12674,
        0.133333,
        0.234432,
        0.098168,
        0.087912,
        0.008791
      ],
      "bid_flow": [
        0.054212,
        0.102564,
        0.072527,
        0.002198,
        0.030037,
        0.193407,
        0.150916,
        0.002198,
        0.011722,
        0.043956,
        0.078388,
        0.060073,
        0.0,
        0.0,
        0.0,
        0.0,
        0.0,
        0.0,
        0.0,
        0.0,
        0.0,
        0.0,
        0.0,
        0.0
      ],
      "side_imbalance": 0.510833,
      "order_density": 0.058824,
      "source_rows": 400,
      "organism_clock": "2025-04-14T09:22:00.316756-04:00"
    },
    {
      "frame_index": 1,
      "timestamp": "2025-04-14T09:22:01.295140-04:00",
      "life_progress": 0.002268,
      "liquidity_density_factor": 0.625,
      "gamma_metabolism_factor": 0.451426,
      "manipulation_factor": 0.0,
      "price_kinetic_factor": 0.0,
      "health_score": 0.808322,
      "health_state": "stable",
      "ask_flow": [
        0.0,
        0.0,
        0.0,
        0.0,
        0.0,
        0.0,
        0.0,
        0.0,
        0.0,
        0.0,
        0.0,
        0.0,
        0.155311,
        0.257875,
        0.704762,
        0.355311,
        0.16337,
        0.151648,
        0.12674,
        0.133333,
        0.234432,
        0.098168,
        0.087912,
        0.008791
      ],
      "bid_flow": [
        0.054212,
        0.102564,
        0.072527,
        0.002198,
        0.030037,
        0.193407,
        0.150916,
        0.002198,
        0.011722,
        0.043956,
        0.078388,
        0.060073,
        0.0,
        0.0,
        0.0,
        0.0,
        0.0,
        0.0,
        0.0,
        0.0,
        0.0,
        0.0,
        0.0,
        0.0
      ],
      "side_imbalance": 0.510833,
      "order_density": 0.058824,
      "source_rows": 400,
      "organism_clock": "2025-04-14T09:22:00.452064-04:00"
    },
    {
      "frame_index": 2,
      "timestamp": "2025-04-14T09:22:01.311097-04:00",
      "life_progress": 0.004535,
      "liquidity_density_factor": 0.625,
      "gamma_metabolism_factor": 0.403033,
      "manipulation_factor": 0.001983,
      "price_kinetic_factor": 0.0,
      "health_score": 0.822146,
      "health_state": "stable",
      "ask_flow": [
        0.0,
        0.0,
        0.0,
        0.0,
        0.0,
        0.0,
        0.0,
        0.0,
        0.0,
        0.0,
        0.0,
        0.0,
        0.153114,
        0.257875,
        0.70696,
        0.355311,
        0.16337,
        0.151648,
        0.12674,
        0.133333,
        0.234432,
        0.098168,
        0.087912,
        0.008791
      ],
      "bid_flow": [
        0.054212,
        0.102564,
        0.072527,
        0.002198,
        0.030037,
        0.193407,
        0.150916,
        0.002198,
        0.011722,
        0.043956,
        0.078388,
        0.060073,
        0.0,
        0.0,
        0.0,
        0.0,
        0.0,
        0.0,
        0.0,
        0.0,
        0.0,
        0.0,
        0.0,
        0.0
      ],
      "side_imbalance": 0.510833,
      "order_density": 0.058824,
      "source_rows": 400,
      "organism_clock": "2025-04-14T09:22:00.587312-04:00"
    },
    {
      "frame_index": 3,
      "timestamp": "2025-04-14T09:22:01.330047-04:00",
      "life_progress": 0.006803,
      "liquidity_density_factor": 0.625,
      "gamma_metabolism_factor": 0.403033,
      "manipulation_factor": 0.001983,
      "price_kinetic_factor": 0.0,
      "health_score": 0.822146,
      "health_state": "stable",
      "ask_flow": [
        0.0,
        0.0,
        0.0,
        0.0,
        0.0,
        0.0,
        0.0,
        0.0,
        0.0,
        0.0,
        0.0,
        0.0,
        0.153114,
        0.257875,
        0.70696,
        0.355311,
        0.16337,
        0.151648,
        0.12674,
        0.133333,
        0.234432,
        0.098168,
        0.087912,
        0.008791
      ],
      "bid_flow": [
        0.054212,
        0.102564,
        0.072527,
        0.002198,
        0.030037,
        0.193407,
        0.150916,
        0.002198,
        0.011722,
        0.043956,
        0.078388,
        0.060073,
        0.0,
        0.0,
        0.0,
        0.0,
        0.0,
        0.0,
        0.0,
        0.0,
        0.0,
        0.0,
        0.0,
        0.0
      ],
      "side_imbalance": 0.510833,
      "order_density": 0.058824,
      "source_rows": 400,
      "organism_clock": "2025-04-14T09:22:00.722620-04:00"
    },
    {
      "frame_index": 4,
      "timestamp": "2025-04-14T09:22:01.346004-04:00",
      "life_progress": 0.00907,
      "liquidity_density_factor": 0.625,
      "gamma_metabolism_factor": 0.403033,
      "manipulation_factor": 0.001983,
      "price_kinetic_factor": 0.0,
      "health_score": 0.822146,
      "health_state": "stable",
      "ask_flow": [
        0.0,
        0.0,
        0.0,
        0.0,
        0.0,
        0.0,
        0.0,
        0.0,
        0.0,
        0.0,
        0.0,
        0.0,
        0.153114,
        0.257875,
        0.70696,
        0.355311,
        0.16337,
        0.151648,
        0.12674,
        0.133333,
        0.234432,
        0.098168,
        0.087912,
        0.008791
      ],
      "bid_flow": [
        0.054212,
        0.102564,
        0.072527,
        0.002198,
        0.030037,
        0.193407,
        0.150916,
        0.002198,
        0.011722,
        0.043956,
        0.078388,
        0.060073,
        0.0,
        0.0,
        0.0,
        0.0,
        0.0,
        0.0,
        0.0,
        0.0,
        0.0,
        0.0,
        0.0,
        0.0
      ],
      "side_imbalance": 0.510833,
      "order_density": 0.058824,
      "source_rows": 400,
      "organism_clock": "2025-04-14T09:22:00.857868-04:00"
    },
    {
      "frame_index": 5,
      "timestamp": "2025-04-14T09:22:01.396868-04:00",
      "life_progress": 0.011338,
      "liquidity_density_factor": 0.625,
      "gamma_metabolism_factor": 0.403033,
      "manipulation_factor": 0.001983,
      "price_kinetic_factor": 0.0,
      "health_score": 0.822146,
      "health_state": "stable",
      "ask_flow": [
        0.0,
        0.0,
        0.0,
        0.0,
        0.0,
        0.0,
        0.0,
        0.0,
        0.0,
        0.0,
        0.0,
        0.0,
        0.153114,
        0.257875,
        0.70696,
        0.355311,
        0.16337,
        0.151648,
        0.12674,
        0.133333,
        0.234432,
        0.098168,
        0.087912,
        0.008791
      ],
      "bid_flow": [
        0.054212,
        0.102564,
        0.072527,
        0.002198,
        0.030037,
        0.193407,
        0.150916,
        0.002198,
        0.011722,
        0.043956,
        0.078388,
        0.060073,
        0.0,
        0.0,
        0.0,
        0.0,
        0.0,
        0.0,
        0.0,
        0.0,
        0.0,
        0.0,
        0.0,
        0.0
      ],
      "side_imbalance": 0.510833,
      "order_density": 0.058824,
      "source_rows": 400,
      "organism_clock": "2025-04-14T09:22:00.993175-04:00"
    },
    {
      "frame_index": 6,
      "timestamp": "2025-04-14T09:22:01.498862-04:00",
      "life_progress": 0.013605,
      "liquidity_density_factor": 0.625,
