analysis/replay/replay_0924.json
{
  "strike_min": 5439.75,
  "strike_max": 5542.25,
  "num_lanes": 24,
  "frames": [
    {
      "frame_index": 0,
      "timestamp": "2025-04-14T09:24:00.093773-04:00",
      "life_progress": 0.0,
      "liquidity_density_factor": 0.766304,
      "gamma_metabolism_factor": 0.806552,
      "manipulation_factor": 0.0,
      "price_kinetic_factor": 0.0,
      "health_score": 0.72298,
      "health_state": "stable",
      "ask_flow": [
        0.0,
        0.0,
        0.0,
        0.0,
        0.0,
        0.0,
        0.0,
        0.0,
        0.0,
        0.0,
        0.0,
        0.012804,
        0.653009,
        0.190781,
        0.943662,
        0.238156,
        1.0,
        0.09475,
        0.455826,
        0.416133,
        0.078105,
        0.197183,
        0.106274,
        0.180538
      ],
      "bid_flow": [
        0.069142,
        0.139565,
        0.126761,
        0.052497,
        0.012804,
        0.076825,
        0.0,
        0.323944,
        0.229193,
        0.121639,
        0.122919,
        0.090909,
        0.0,
        0.0,
        0.0,
        0.0,
        0.0,
        0.0,
        0.0,
        0.0,
        0.0,
        0.0,
        0.0,
        0.0
      ],
      "side_imbalance": 0.539491,
      "order_density": 0.5,
      "source_rows": 400,
      "organism_clock": "2025-04-14T09:24:00.093773-04:00"
    },
    {
      "frame_index": 1,
      "timestamp": "2025-04-14T09:24:01.305533-04:00",
      "life_progress": 0.002128,
      "liquidity_density_factor": 0.766304,
      "gamma_metabolism_factor": 0.80703,
      "manipulation_factor": 0.0,
      "price_kinetic_factor": 0.25,
      "health_score": 0.672837,
      "health_state": "stable",
      "ask_flow": [
        0.0,
        0.0,
        0.0,
        0.0,
        0.0,
        0.0,
        0.0,
        0.0,
        0.0,
        0.0,
        0.0,
        0.012804,
        0.653009,
        0.190781,
        0.943662,
        0.238156,
        1.0,
        0.09475,
        0.455826,
        0.416133,
        0.078105,
        0.197183,
        0.106274,
        0.180538
      ],
      "bid_flow": [
        0.069142,
        0.139565,
        0.126761,
        0.052497,
        0.012804,
        0.076825,
        0.0,
        0.323944,
        0.229193,
        0.121639,
        0.122919,
        0.090909,
        0.0,
        0.0,
        0.0,
        0.0,
        0.0,
        0.0,
        0.0,
        0.0,
        0.0,
        0.0,
        0.0,
        0.0
      ],
      "side_imbalance": 0.539491,
      "order_density": 0.5,
      "source_rows": 400,
      "organism_clock": "2025-04-14T09:24:00.221013-04:00"
    },
    {
      "frame_index": 2,
      "timestamp": "2025-04-14T09:24:01.336451-04:00",
      "life_progress": 0.004255,
      "liquidity_density_factor": 0.907609,
      "gamma_metabolism_factor": 0.838131,
      "manipulation_factor": 0.0,
      "price_kinetic_factor": 0.0,
      "health_score": 0.734702,
      "health_state": "stable",
      "ask_flow": [
        0.0,
        0.0,
        0.0,
        0.0,
        0.0,
        0.0,
        0.0,
        0.0,
        0.0,
        0.0,
        0.0,
        0.012804,
        0.653009,
        0.190781,
        0.943662,
        0.238156,
        1.0,
        0.09475,
        0.455826,
        0.416133,
        0.078105,
        0.197183,
        0.106274,
        0.180538
      ],
      "bid_flow": [
        0.102433,
        0.139565,
        0.126761,
        0.052497,
        0.012804,
        0.076825,
        0.0,
        0.323944,
        0.229193,
        0.121639,
        0.122919,
        0.090909,
        0.0,
        0.0,
        0.0,
        0.0,
        0.0,
        0.0,
        0.0,
        0.0,
        0.0,
        0.0,
        0.0,
        0.0
      ],
      "side_imbalance": 0.530901,
      "order_density": 0.785714,
      "source_rows": 400,
      "organism_clock": "2025-04-14T09:24:00.348193-04:00"
    },
    {
      "frame_index": 3,
      "timestamp": "2025-04-14T09:24:01.409256-04:00",
      "life_progress": 0.006383,
      "liquidity_density_factor": 0.907609,
      "gamma_metabolism_factor": 0.838131,
      "manipulation_factor": 0.0,
      "price_kinetic_factor": 0.0,
      "health_score": 0.734702,
      "health_state": "stable",
      "ask_flow": [
        0.0,
        0.0,
        0.0,
        0.0,
        0.0,
        0.0,
        0.0,
        0.0,
        0.0,
        0.0,
        0.0,
        0.012804,
        0.653009,
        0.190781,
        0.943662,
        0.238156,
        1.0,
        0.09475,
        0.455826,
        0.416133,
        0.078105,
        0.197183,
        0.106274,
        0.180538
      ],
      "bid_flow": [
        0.102433,
        0.139565,
        0.126761,
        0.052497,
        0.012804,
        0.076825,
        0.0,
        0.323944,
        0.229193,
        0.121639,
        0.122919,
        0.090909,
        0.0,
        0.0,
        0.0,
        0.0,
        0.0,
        0.0,
        0.0,
        0.0,
        0.0,
        0.0,
        0.0,
        0.0
      ],
      "side_imbalance": 0.530901,
      "order_density": 0.785714,
      "source_rows": 400,
      "organism_clock": "2025-04-14T09:24:00.475433-04:00"
    },
    {
      "frame_index": 4,
      "timestamp": "2025-04-14T09:24:01.428205-04:00",
      "life_progress": 0.008511,
      "liquidity_density_factor": 0.907609,
      "gamma_metabolism_factor": 0.838131,
      "manipulation_factor": 0.0,
      "price_kinetic_factor": 0.0,
      "health_score": 0.734702,
      "health_state": "stable",
      "ask_flow": [
        0.0,
        0.0,
        0.0,
        0.0,
        0.0,
        0.0,
        0.0,
        0.0,
        0.0,
        0.0,
        0.0,
        0.012804,
        0.653009,
        0.190781,
        0.943662,
        0.238156,
        1.0,
        0.09475,
        0.455826,
        0.416133,
        0.078105,
        0.197183,
        0.106274,
        0.180538
      ],
      "bid_flow": [
        0.102433,
        0.139565,
        0.126761,
        0.052497,
        0.012804,
        0.076825,
        0.0,
        0.323944,
        0.229193,
        0.121639,
        0.122919,
        0.090909,
        0.0,
        0.0,
        0.0,
        0.0,
        0.0,
        0.0,
        0.0,
        0.0,
        0.0,
        0.0,
        0.0,
        0.0
      ],
      "side_imbalance": 0.530901,
      "order_density": 0.785714,
      "source_rows": 400,
      "organism_clock": "2025-04-14T09:24:00.602673-04:00"
    },
    {
      "frame_index": 5,
      "timestamp": "2025-04-14T09:24:01.446157-04:00",
      "life_progress": 0.010638,
      "liquidity_density_factor": 0.907609,
      "gamma_metabolism_factor": 0.838131,
      "manipulation_factor": 0.0,
      "price_kinetic_factor": 0.0,
      "health_score": 0.734702,
      "health_state": "stable",
      "ask_flow": [
        0.0,
        0.0,
        0.0,
        0.0,
        0.0,
        0.0,
        0.0,
        0.0,
        0.0,
        0.0,
        0.0,
        0.012804,
        0.653009,
        0.190781,
        0.943662,
        0.238156,
        1.0,
        0.09475,
        0.455826,
        0.416133,
        0.078105,
        0.197183,
        0.106274,
        0.180538
      ],
      "bid_flow": [
        0.102433,
        0.139565,
        0.126761,
        0.052497,
        0.012804,
        0.076825,
        0.0,
        0.323944,
        0.229193,
        0.121639,
        0.122919,
        0.090909,
        0.0,
        0.0,
        0.0,
        0.0,
        0.0,
        0.0,
        0.0,
        0.0,
        0.0,
        0.0,
        0.0,
        0.0
      ],
      "side_imbalance": 0.530901,
      "order_density": 0.785714,
      "source_rows": 400,
      "organism_clock": "2025-04-14T09:24:00.729853-04:00"
    },
    {
      "frame_index": 6,
      "timestamp": "2025-04-14T09:24:01.469096-04:00",
      "life_progress": 0.012766,
      "liquidity_density_factor": 0.907609,
      "gamma_metabolism_factor": 0.838131,
